Workbook
Name _: #REF!
Name ____________dec10: #REF!
Name ___________dec10: #REF!
Name __________dec10: #REF!
Name _________dec10: #REF!
Name ________dec10: #REF!
Name _______dec10: #REF!
Name _______oct98: #REF!
Name ______dec10: #REF!
Name ______OCT334: #REF!
Name ______oct98: #REF!
Name _____dec10: #REF!
Name _____FMC1: #REF!
Name _____OCT334: #REF!
Name _____oct98: #REF!
Name ____dec10: #REF!
Name ____FMC1: #REF!
Name ____OCT334: #REF!
Name ____oct98: #REF!
Name ___DAT12: #REF!
Name ___DAT8: #REF!
Name ___DAT9: #REF!
Name ___dec10: #REF!
Name ___FMC1: #REF!
Name ___OCT334: #REF!
Name ___oct98: #REF!
Name __ACT1: #REF!
Name __ACT2: #REF!
Name __ADJ1: #REF!
Name __ADJ2: #REF!
Name __aje1: #REF!
Name __c: #REF!
Name __CAP1: #REF!
Name __cap2: #REF!
Name __cap3: #REF!
Name __cap4: #REF!
Name __cap5: #REF!
Name __cog1: #REF!
Name __cog2: #REF!
Name __DAT1: #REF!
Name __DAT10: #REF!
Name __DAT11: #REF!
Name __DAT2: #REF!
Name __DAT3: #REF!
Name __DAT4: #REF!
Name __DAT5: #REF!
Name __DAT6: #REF!
Name __DAT7: #REF!
Name __dec10: #REF!
Name __E32: #REF!
Name __E5: #REF!
Name __F2: #REF!
Name __FMC1: #REF!
Name __JA2: #REF!
Name __lam1: #REF!
Name __lam2: #REF!
Name __Lam3: #REF!
Name __Lam4: #REF!
Name __Lam5: #REF!
Name __LD1: #N/A

Sheet To request
A1: 1.Maintain a price list for different equipment model in system for auto calculate leasing (staff to update in system when have changes in price / add on model)
A2: 2.Develope a module for Rent-to-own prodecures (from invoicing until leasing accounting entry)
A5: *To comply Lessor accounting (as our contract mentioned agreement shall commence on the date of the equipment is delivered - risk and right has based to customer upon deliver & install), when stock out for installation - then need to calculate lease receivable

Sheet price list
B2: Ice Maker Machine Price List
B4: No | C4: Model | D4: Type of Ice | E4: Short-term | F4: Lease | G4: R-t-O | I4: Outright | K4: Sort helper
E5: 6 months | F5: 12 months | G5: 24 months (fixed) | H5: 24 months (Quote) | I5: One-off Price (Dealer/Fixed) | J5: One-off Price (Quote)
B6: 1 | C6: GR-CI100 | D6: Cube Ice | E6: 0 | F6: 0 | G6: 0 | H6: 0 | I6: 5899 | J6: 6599 | K6: CI100
B7: 2 | C7: GR-CI150 | D7: Cube Ice | E7: 0 | F7: 0 | G7: 369 | H7: 399 | I7: 6599 | J7: 7599 | K7: CI150
B8: 3 | C8: GR-CI500 | D8: Cube Ice | E8: 699 | F8: 679 | G8: 639 | H8: 639 | I8: 10999 | J8: 12999 | K8: CI500
B9: 4 | C9: GR-CI700 | D9: Cube Ice | E9: 1199 | F9: 999 | G9: 799 | H9: 999 | I9: 12999 | J9: 14999 | K9: CI700
B10: 5 | C10: GR-NI1050 | D10: Nugget Ice | E10: 2099 | F10: 1699 | G10: 1199 | H10: 1299 | I10: 21999 | J10: 24999 | K10: NI1050
B13: Dishwasher Machine Price List
B15: No | C15: Model | E15: Short-term | F15: Lease | G15: R-t-O | I15: R-t-O | J15: Outright
E16: 6 months | F16: 12 months | G16: 36 months (fixed) | H16: 36 months (Quote) | I16: 36 months (w/o Detergent) | J16: One-off List Price (fixed) | K16: Cost
B17: 1 | C17: U1M | D17: Under Counter | E17: 0 | F17: 600 | G17: 350 | H17: 399 | I17: 300 | J17: 12888
B18: 2 | C18: D1M | D18: Door Lift | E18: 0 | F18: 888 | G18: 550 | H18: 699 | I18: 450 | J18: 16888
B19: 4 | C19: DPCR1 | D19: One Tank Conveyor | E19: 0 | F19: 2788 | G19: 1688 | H19: 1699 | I19: 1299 | J19: 48888
B20: 5 | C20: DPCR2 | D20: Two Tank Conveyor | E20: 0 | F20: 4188 | G20: 2088 | H20: 2999 | I20: 1999 | J20: 68888

Sheet List of customer
A1: No | B1: Contract number | C1: Nature | D1: Customer | E1: Contract start | F1: Contract end | G1: Contract period | H1: Deposit | I1: Month of deposit | J1: Monthly rental | K1: Installation Date | L1: Product Type | M1: S/N Number | N1: Cost | O1: Rent at quoted price? | P1: Outright Price | Q1: Maintenance Rate | R1: Dishwasher - with Detergent? | S1: Maintenance covered | T1: Hyperlink to PV Schedule | U1: Remarks
A2: 1 | B2: SO25-0001 | C2: Rent-to-own Dishwasher | D2: HAKATA F&B SDN BHD | E2: 45717 | F2: 46811 | G2: 36 months | H2: =J2*2 -> 798 | I2: 2 | J2: 399 | K2: - | L2: D1M | M2: S/N: TC 2401764 | N2: 10000 | O2: =CustomerList[[#This Row],[Monthly rental]]/IF(ISNUMBER(SEARCH("ice machine",CustomerList[[#This Row],[Nature]])),IFERROR(INDEX('price list'!$H$6:$H$10,MATCH(CustomerList[[#This Row],[Product Type]],'price list'!$K$6:$K$10,0)),""),IF(ISNUMBER(SEARCH("dishwasher",CustomerList[[#This Row],[Nature]])),IF(CustomerList[[#This Row],[Dishwasher - with Detergent?]]="With",IFERROR(INDEX('price list'!$H$17:$H$20,MATCH(CustomerList[[#This Row],[Product Type]],'price list'!$C$17:$C$20,0)),""),IFERROR(INDEX('price list'!$I$17:$I$20,MATCH(CustomerList[[#This Row],[Product Type]],'price list'!$C$17:$C$20,0)),"")))) -> 0.88666667 | P2: =(IF(ISNUMBER(SEARCH("ice machine",CustomerList[[#This Row],[Nature]])),IFERROR(INDEX('price list'!$J$6:$J$10,MATCH(CustomerList[[#This Row],[Product Type]],'price list'!$K$6:$K$10,0)),""),IF(ISNUMBER(SEARCH("Dishwasher",CustomerList[[#This Row],[Nature]])),IFERROR(INDEX('price list'!$J$17:$J$20,MATCH(CustomerList[[#This Row],[Product Type]],'price list'!$C$17:$C$20,0)),""),))+IF(ISNUMBER(SEARCH("Rent-to-own",CustomerList[[#This Row],[Nature]])),CustomerList[[#This Row],[Maintenance Rate]],0)*(LEFT(CustomerList[[#This Row],[Maintenance covered]],1)-1))*CustomerList[[#This Row],[Rent at quoted price?]] -> 20068.813 | Q2: =IFERROR(IF(SEARCH("ice machine",CustomerList[[#This Row],[Nature]]),2288,0),IF(SEARCH("Dishwasher",CustomerList[[#This Row],[Nature]]),((LEFT(CustomerList[[#This Row],[Contract period]],2)/12*6-1)*507/(LEFT(CustomerList[[#This Row],[Contract period]],2)/12)),0)) -> 2873 | R2: Without | S2: =IF(ISNUMBER(SEARCH("Rental",C2)),"1 year",IF(ISNUMBER(SEARCH("Rent-to-own",CustomerList[[#This Row],[Nature]])),LEFT(G2,2)/12&" years","Check")) -> 3 years | T2: =HYPERLINK("#'"&B2&"'!A1","Go to contract") -> Go to contract
A3: 2 | B3: SO25-0006 | C3: Rent-to-own Dishwasher | D3: KAM KITCHENS HOME SDN BHD | E3: 45809 | F3: 46904 | G3: 36 months | H3: 1398 | I3: 2 | J3: =H3/2 -> 699 | K3: - | L3: D1M | M3: S/R: TC 2402208 | N3: 10000 | O3: =CustomerList[[#This Row],[Monthly rental]]/IF(ISNUMBER(SEARCH("ice machine",CustomerList[[#This Row],[Nature]])),IFERROR(INDEX('price list'!$H$6:$H$10,MATCH(CustomerList[[#This Row],[Product Type]],'price list'!$K$6:$K$10,0)),""),IF(ISNUMBER(SEARCH("dishwasher",CustomerList[[#This Row],[Nature]])),IF(CustomerList[[#This Row],[Dishwasher - with Detergent?]]="With",IFERROR(INDEX('price list'!$H$17:$H$20,MATCH(CustomerList[[#This Row],[Product Type]],'price list'!$C$17:$C$20,0)),""),IFERROR(INDEX('price list'!$I$17:$I$20,MATCH(CustomerList[[#This Row],[Product Type]],'price list'!$C$17:$C$20,0)),"")))) -> 1 | P3: =(IF(ISNUMBER(SEARCH("ice machine",CustomerList[[#This Row],[Nature]])),IFERROR(INDEX('price list'!$J$6:$J$10,MATCH(CustomerList[[#This Row],[Product Type]],'price list'!$K$6:$K$10,0)),""),IF(ISNUMBER(SEARCH("Dishwasher",CustomerList[[#This Row],[Nature]])),IFERROR(INDEX('price list'!$J$17:$J$20,MATCH(CustomerList[[#This Row],[Product Type]],'price list'!$C$17:$C$20,0)),""),))+IF(ISNUMBER(SEARCH("Rent-to-own",CustomerList[[#This Row],[Nature]])),CustomerList[[#This Row],[Maintenance Rate]],0)*(LEFT(CustomerList[[#This Row],[Maintenance covered]],1)-1))*CustomerList[[#This Row],[Rent at quoted price?]] -> 22634 | Q3: =IFERROR(IF(SEARCH("ice machine",CustomerList[[#This Row],[Nature]]),2288,0),IF(SEARCH("Dishwasher",CustomerList[[#This Row],[Nature]]),((LEFT(CustomerList[[#This Row],[Contract period]],2)/12*6-1)*507/(LEFT(CustomerList[[#This Row],[Contract period]],2)/12)),0)) -> 2873 | R3: With | S3: =IF(ISNUMBER(SEARCH("Rental",C3)),"1 year",IF(ISNUMBER(SEARCH("Rent-to-own",CustomerList[[#This Row],[Nature]])),LEFT(G3,2)/12&" years","Check")) -> 3 years | T3: =HYPERLINK("#'"&B3&"'!A1","Go to contract") -> Go to contract
A4: 3 | B4: SO25-0135 | C4: Rent-to-own ice machine | D4: Craven F&B | E4: 45962 | F4: 46691 | G4: 24 months | H4: 1700 | I4: 2 | J4: =H4/I4 -> 850 | K4: 45931 | L4: NI1050 | M4: NI 1050, S/N: ZJS250809A0052A | N4: 13451.699 | O4: =CustomerList[[#This Row],[Monthly rental]]/IF(ISNUMBER(SEARCH("ice machine",CustomerList[[#This Row],[Nature]])),IFERROR(INDEX('price list'!$H$6:$H$10,MATCH(CustomerList[[#This Row],[Product Type]],'price list'!$K$6:$K$10,0)),""),IF(ISNUMBER(SEARCH("dishwasher",CustomerList[[#This Row],[Nature]])),IF(CustomerList[[#This Row],[Dishwasher - with Detergent?]]="With",IFERROR(INDEX('price list'!$H$17:$H$20,MATCH(CustomerList[[#This Row],[Product Type]],'price list'!$C$17:$C$20,0)),""),IFERROR(INDEX('price list'!$I$17:$I$20,MATCH(CustomerList[[#This Row],[Product Type]],'price list'!$C$17:$C$20,0)),"")))) -> 0.6543495 | P4: =(IF(ISNUMBER(SEARCH("ice machine",CustomerList[[#This Row],[Nature]])),IFERROR(INDEX('price list'!$J$6:$J$10,MATCH(CustomerList[[#This Row],[Product Type]],'price list'!$K$6:$K$10,0)),""),IF(ISNUMBER(SEARCH("Dishwasher",CustomerList[[#This Row],[Nature]])),IFERROR(INDEX('price list'!$J$17:$J$20,MATCH(CustomerList[[#This Row],[Product Type]],'price list'!$C$17:$C$20,0)),""),))+IF(ISNUMBER(SEARCH("Rent-to-own",CustomerList[[#This Row],[Nature]])),CustomerList[[#This Row],[Maintenance Rate]],0)*(LEFT(CustomerList[[#This Row],[Maintenance covered]],1)-1))*CustomerList[[#This Row],[Rent at quoted price?]] -> 17855.235 | Q4: =IFERROR(IF(SEARCH("ice machine",CustomerList[[#This Row],[Nature]]),2288,0),IF(SEARCH("Dishwasher",CustomerList[[#This Row],[Nature]]),((LEFT(CustomerList[[#This Row],[Contract period]],2)/12*6-1)*507/(LEFT(CustomerList[[#This Row],[Contract period]],2)/12)),0)) -> 2288 | R4: N/A | S4: =IF(ISNUMBER(SEARCH("Rental",C4)),"1 year",IF(ISNUMBER(SEARCH("Rent-to-own",CustomerList[[#This Row],[Nature]])),LEFT(G4,2)/12&" years","Check")) -> 2 years | T4: =HYPERLINK("#'"&B4&"'!A1","Go to contract") -> Go to contract
A5: 4 | B5: SO25-0138 | C5: Rent-to-own ice machine | D5: Nyonya Recipe | E5: 45946 | F5: 46675 | G5: 24 months | H5: 1278 | I5: 2 | J5: =H5/I5 -> 639 | K5: 45946 | L5: CI500 | M5: CI500A-M 23*23*23, S/N: ZJS250823A0088A | N5: 5517.6629 | O5: =CustomerList[[#This Row],[Monthly rental]]/IF(ISNUMBER(SEARCH("ice machine",CustomerList[[#This Row],[Nature]])),IFERROR(INDEX('price list'!$H$6:$H$10,MATCH(CustomerList[[#This Row],[Product Type]],'price list'!$K$6:$K$10,0)),""),IF(ISNUMBER(SEARCH("dishwasher",CustomerList[[#This Row],[Nature]])),IF(CustomerList[[#This Row],[Dishwasher - with Detergent?]]="With",IFERROR(INDEX('price list'!$H$17:$H$20,MATCH(CustomerList[[#This Row],[Product Type]],'price list'!$C$17:$C$20,0)),""),IFERROR(INDEX('price list'!$I$17:$I$20,MATCH(CustomerList[[#This Row],[Product Type]],'price list'!$C$17:$C$20,0)),"")))) -> 1 | P5: =(IF(ISNUMBER(SEARCH("ice machine",CustomerList[[#This Row],[Nature]])),IFERROR(INDEX('price list'!$J$6:$J$10,MATCH(CustomerList[[#This Row],[Product Type]],'price list'!$K$6:$K$10,0)),""),IF(ISNUMBER(SEARCH("Dishwasher",CustomerList[[#This Row],[Nature]])),IFERROR(INDEX('price list'!$J$17:$J$20,MATCH(CustomerList[[#This Row],[Product Type]],'price list'!$C$17:$C$20,0)),""),))+IF(ISNUMBER(SEARCH("Rent-to-own",CustomerList[[#This Row],[Nature]])),CustomerList[[#This Row],[Maintenance Rate]],0)*(LEFT(CustomerList[[#This Row],[Maintenance covered]],1)-1))*CustomerList[[#This Row],[Rent at quoted price?]] -> 15287 | Q5: =IFERROR(IF(SEARCH("ice machine",CustomerList[[#This Row],[Nature]]),2288,0),IF(SEARCH("Dishwasher",CustomerList[[#This Row],[Nature]]),((LEFT(CustomerList[[#This Row],[Contract period]],2)/12*6-1)*507/(LEFT(CustomerList[[#This Row],[Contract period]],2)/12)),0)) -> 2288 | R5: N/A | S5: =IF(ISNUMBER(SEARCH("Rental",C5)),"1 year",IF(ISNUMBER(SEARCH("Rent-to-own",CustomerList[[#This Row],[Nature]])),LEFT(G5,2)/12&" years","Check")) -> 2 years | T5: =HYPERLINK("#'"&B5&"'!A1","Go to contract") -> Go to contract
A6: 5 | B6: SO25-0172 | C6: Rent-to-own Dishwasher | D6: Goldhill Reserve Sdn Bhd | E6: 46023 | F6: 47118 | G6: 36 months | H6: 1398 | I6: 2 | J6: 699 | K6: 46014 | L6: D1M | M6: S/N: TC 2500819 | N6: 10000 | O6: =CustomerList[[#This Row],[Monthly rental]]/IF(ISNUMBER(SEARCH("ice machine",CustomerList[[#This Row],[Nature]])),IFERROR(INDEX('price list'!$H$6:$H$10,MATCH(CustomerList[[#This Row],[Product Type]],'price list'!$K$6:$K$10,0)),""),IF(ISNUMBER(SEARCH("dishwasher",CustomerList[[#This Row],[Nature]])),IF(CustomerList[[#This Row],[Dishwasher - with Detergent?]]="With",IFERROR(INDEX('price list'!$H$17:$H$20,MATCH(CustomerList[[#This Row],[Product Type]],'price list'!$C$17:$C$20,0)),""),IFERROR(INDEX('price list'!$I$17:$I$20,MATCH(CustomerList[[#This Row],[Product Type]],'price list'!$C$17:$C$20,0)),"")))) -> 1 | P6: =(IF(ISNUMBER(SEARCH("ice machine",CustomerList[[#This Row],[Nature]])),IFERROR(INDEX('price list'!$J$6:$J$10,MATCH(CustomerList[[#This Row],[Product Type]],'price list'!$K$6:$K$10,0)),""),IF(ISNUMBER(SEARCH("Dishwasher",CustomerList[[#This Row],[Nature]])),IFERROR(INDEX('price list'!$J$17:$J$20,MATCH(CustomerList[[#This Row],[Product Type]],'price list'!$C$17:$C$20,0)),""),))+IF(ISNUMBER(SEARCH("Rent-to-own",CustomerList[[#This Row],[Nature]])),CustomerList[[#This Row],[Maintenance Rate]],0)*(LEFT(CustomerList[[#This Row],[Maintenance covered]],1)-1))*CustomerList[[#This Row],[Rent at quoted price?]] -> 22634 | Q6: =IFERROR(IF(SEARCH("ice machine",CustomerList[[#This Row],[Nature]]),2288,0),IF(SEARCH("Dishwasher",CustomerList[[#This Row],[Nature]]),((LEFT(CustomerList[[#This Row],[Contract period]],2)/12*6-1)*507/(LEFT(CustomerList[[#This Row],[Contract period]],2)/12)),0)) -> 2873 | R6: With | S6: =IF(ISNUMBER(SEARCH("Rental",C6)),"1 year",IF(ISNUMBER(SEARCH("Rent-to-own",CustomerList[[#This Row],[Nature]])),LEFT(G6,2)/12&" years","Check")) -> 3 years | T6: =HYPERLINK("#'"&B6&"'!A1","Go to contract") -> Go to contract
P20: =('price list'!J18+'List of customer'!Q2*2)*O2 -> 20068.813

Sheet SO25-0001
A1: =IFERROR(INDEX('List of customer'!D:D,MATCH($S$1,'List of customer'!$B:$B,0)),"") -> HAKATA F&B SDN BHD | K1: Year end | L1: 46022 | S1: {=MID(CELL("filename",A1),FIND("]",CELL("filename",A1))+1,255)} -> SO25-0001 | Z1: SO25-0001
E2: Account double entry (REVENUE RECOGNITION) | I2: =SUM(I3:I18) -> 0 | K2: Year beginning | L2: 45658
A3: INPUTS | C3: =IFERROR(INDEX('List of customer'!C:C,MATCH($S$1,'List of customer'!$B:$B,0)),"") -> Rent-to-own Dishwasher | E3: Initial recognition
A4: Machine cost (inventory) | C4: =IFERROR(INDEX('List of customer'!N:N,MATCH($S$1,'List of customer'!$B:$B,0)),"") -> 10000 | E4: Dr Lease receivables | I4: =$C$39 -> 11449.813 | J4: <= Total principal
A5: Lease term (months) | C5: =LEFT(IFERROR(INDEX('List of customer'!G:G,MATCH($S$1,'List of customer'!$B:$B,0)),""),2) -> 36 | E5: Cr Revenue - finance lease selling price | I5: =-C25 -> -4579.4471 | J5: <= Machine proportion of principal
A6: Contract start | C6: =IFERROR(INDEX('List of customer'!E:E,MATCH($S$1,'List of customer'!$B:$B,0)),"") -> 45717 | E6: Cr Deferred revenue - maintenance | I6: =-C26 -> -6870.3663 | J6: <= Maintenance proportion of principal
A7: Contract end | C7: =IFERROR(INDEX('List of customer'!F:F,MATCH($S$1,'List of customer'!$B:$B,0)),"") -> 46811
A8: Monthly lease payment | C8: =IFERROR(INDEX('List of customer'!J:J,MATCH($S$1,'List of customer'!$B:$B,0)),"") -> 399 | E8: Dr Cost of Sales | I8: =C32 -> 10000
A9: Option 1: Cash selling price | C9: =C17 -> 11449.813 | E9: Cr Inventory | I9: =-I8 -> -10000 | J9: <= Inventory cost of machine
A11: Use selling price? Enter "Yes" or "No" | C11: =IF(C9=0,"No","Yes") -> Yes | E11: Recognition of maintenance
E12: Dr Deferred revenue - maintenance | I12: =-I6/$C$5*COUNTIFS($B$39:$B$74,"<="&$L$1,$E$39:$E$74,">"&0,$B$39:$B$74,">="&$L$2) -> 1908.4351 | J12: <= Maintenance charged on straight-line basis
A13: Cash selling price | E13: Cr Revenue - maintenance | I13: =-I12 -> -1908.4351
A14: Outright price | C14: =IFERROR(INDEX('List of customer'!P:P,MATCH($S$1,'List of customer'!$B:$B,0)),"") -> 20068.813
A15: Maintenance rate | C15: =IFERROR(INDEX('List of customer'!Q:Q,MATCH($S$1,'List of customer'!$B:$B,0)),"") -> 2873 | E15: Dr Bank | I15: =SUMIFS($E$39:$E$74,$B$39:$B$74,"<="&$L$1,$B$39:$B$74,">="&$L$2) -> 3990 | J15: <= Lease payment received
A16: Included for (years) | C16: =LEFT(IFERROR(INDEX('List of customer'!S:S,MATCH($S$1,'List of customer'!$B:$B,0)),""),1) -> 3 | E16: Cr Lease receivables | I16: =-SUMIFS($F$39:$F$74,$B$39:$B$74,"<="&$L$1,$B$39:$B$74,">="&$L$2) -> -2673.8237 | J16: <= Principal portion of lease payment received
A17: Net outright price for machine | C17: =C14-C15*C16 -> 11449.813 | E17: Cr Revenue - finance interest income | I17: =-SUMIFS($D$39:$D$74,$B$39:$B$74,"<="&$L$1,$B$39:$B$74,">="&$L$2) -> -1316.1763 | J17: <= Interest portion of lease payment received
A19: Lease payment proportion
A20: Total lease payment | C20: =C5*C8 -> 14364
A21: Total maintenance fee | C21: =C15*C16 -> 8619 | D21: <= Maintenance price is fixed across the timeline
A22: Total payable for machine | C22: =C20-C21 -> 5745
A24: Lease principal proportion
A25: Lease portion | C25: =$C$22/$C$20*$C$30 -> 4579.4471
A26: Maintenance portion | C26: =$C$21/$C$20*$C$30 -> 6870.3663
A28: Derived calculations
A29: Monthly discount rate used | C29: =IF(UPPER($C$11)="YES",RATE($C$5,-$C$8,$C$9,0,0),$C$10) -> 0.012809922 | D29: INTEREST | E29: 0.012809922
A30: Net investment in lease (PV of lease payments) | C30: =IF(UPPER($C$11)="YES",$C$9,PV($C$29,$C$5,-$C$8,0,0)) -> 11449.813
A31: Revenue at commencement | C31: =C30 -> 11449.813
A32: Cost of sales at commencement | C32: =IFERROR(INDEX('List of customer'!N:N,MATCH($S$1,'List of customer'!$B:$B,0)),"") -> 10000
A33: Selling profit at commencement | C33: =C31-C32 -> 1449.8133
A37: Amortisation schedule | D37: Interest | E37: Rent to Own monthly fee
A38: Period | B38: Date | C38: Opening balance | D38: Finance income | E38: Cash received | F38: Principal reduction | G38: Closing balance
A39: 1 | B39: =$C$6 -> 45717 | C39: =C30 -> 11449.813 | D39: =C39*$C$29 -> 146.67122 | E39: =IF(C39<=1,0,$C$8) -> 399 | F39: =E39-D39 -> 252.32878 | G39: =C39-F39 -> 11197.485
A40: 2 | B40: =EDATE(B39,1) -> 45748 | C40: =IF(G39<=0,0,G39) -> 11197.485 | D40: =C40*$C$29 -> 143.43891 | E40: =IF(C40<=1,0,$C$8) -> 399 | F40: =E40-D40 -> 255.56109 | G40: =C40-F40 -> 10941.923
A41: 3 | B41: =EDATE(B40,1) -> 45778 | C41: =IF(G40<=0,0,G40) -> 10941.923 | D41: =C41*$C$29 -> 140.16519 | E41: =IF(C41<=1,0,$C$8) -> 399 | F41: =E41-D41 -> 258.83481 | G41: =C41-F41 -> 10683.089
A42: 4 | B42: =EDATE(B41,1) -> 45809 | C42: =IF(G41<=0,0,G41) -> 10683.089 | D42: =C42*$C$29 -> 136.84953 | E42: =IF(C42<=1,0,$C$8) -> 399 | F42: =E42-D42 -> 262.15047 | G42: =C42-F42 -> 10420.938
A43: 5 | B43: =EDATE(B42,1) -> 45839 | C43: =IF(G42<=0,0,G42) -> 10420.938 | D43: =C43*$C$29 -> 133.49141 | E43: =IF(C43<=1,0,$C$8) -> 399 | F43: =E43-D43 -> 265.50859 | G43: =C43-F43 -> 10155.43
A44: 6 | B44: =EDATE(B43,1) -> 45870 | C44: =IF(G43<=0,0,G43) -> 10155.43 | D44: =C44*$C$29 -> 130.09026 | E44: =IF(C44<=1,0,$C$8) -> 399 | F44: =E44-D44 -> 268.90974 | G44: =C44-F44 -> 9886.5199
A45: 7 | B45: =EDATE(B44,1) -> 45901 | C45: =IF(G44<=0,0,G44) -> 9886.5199 | D45: =C45*$C$29 -> 126.64555 | E45: =IF(C45<=1,0,$C$8) -> 399 | F45: =E45-D45 -> 272.35445 | G45: =C45-F45 -> 9614.1654
A46: 8 | B46: =EDATE(B45,1) -> 45931 | C46: =IF(G45<=0,0,G45) -> 9614.1654 | D46: =C46*$C$29 -> 123.15671 | E46: =IF(C46<=1,0,$C$8) -> 399 | F46: =E46-D46 -> 275.84329 | G46: =C46-F46 -> 9338.3221
A47: 9 | B47: =EDATE(B46,1) -> 45962 | C47: =IF(G46<=0,0,G46) -> 9338.3221 | D47: =C47*$C$29 -> 119.62318 | E47: =IF(C47<=1,0,$C$8) -> 399 | F47: =E47-D47 -> 279.37682 | G47: =C47-F47 -> 9058.9453
...

Sheet SO25-0006
A1: =IFERROR(INDEX('List of customer'!D:D,MATCH($S$1,'List of customer'!$B:$B,0)),"") -> KAM KITCHENS HOME SDN BHD | K1: Year end | L1: 46022 | S1: {=MID(CELL("filename",A1),FIND("]",CELL("filename",A1))+1,255)} -> SO25-0006 | Z1: SO25-0006
E2: Account double entry | I2: =SUM(I3:I18) -> 0 | K2: Year beginning | L2: 45658
A3: INPUTS | C3: =IFERROR(INDEX('List of customer'!C:C,MATCH($S$1,'List of customer'!$B:$B,0)),"") -> Rent-to-own Dishwasher | E3: Initial recognition
A4: Machine cost (inventory) | C4: =IFERROR(INDEX('List of customer'!N:N,MATCH($S$1,'List of customer'!$B:$B,0)),"") -> 10000 | E4: Dr Lease receivables | I4: =$C$39 -> 14015 | J4: <= Total principal
A5: Lease term (months) | C5: =LEFT(IFERROR(INDEX('List of customer'!G:G,MATCH($S$1,'List of customer'!$B:$B,0)),""),2) -> 36 | E5: Cr Revenue - finance lease selling price | I5: =-C25 -> -9214.6787 | J5: <= Machine proportion of principal
A6: Contract start | C6: =IFERROR(INDEX('List of customer'!E:E,MATCH($S$1,'List of customer'!$B:$B,0)),"") -> 45809 | E6: Cr Deferred revenue - maintenance | I6: =-C26 -> -4800.3213 | J6: <= Maintenance proportion of principal
A7: Contract end | C7: =IFERROR(INDEX('List of customer'!F:F,MATCH($S$1,'List of customer'!$B:$B,0)),"") -> 46904
A8: Monthly lease payment | C8: =IFERROR(INDEX('List of customer'!J:J,MATCH($S$1,'List of customer'!$B:$B,0)),"") -> 699 | E8: Dr Cost of Sales | I8: =C32 -> 10000
A9: Option 1: Cash selling price | C9: =C17 -> 14015 | E9: Cr Inventory | I9: =-I8 -> -10000 | J9: <= Inventory cost of machine
A11: Use selling price? Enter "Yes" or "No" | C11: =IF(C9=0,"No","Yes") -> Yes | E11: Recognition of maintenance
E12: Dr Deferred revenue - maintenance | I12: =-I6/$C$5*COUNTIFS($B$39:$B$74,"<="&$L$1,$E$39:$E$74,">"&0,$B$39:$B$74,">="&$L$2) -> 933.39581 | J12: <= Maintenance charged on straight-line basis
A13: Cash selling price | E13: Cr Revenue - maintenance | I13: =-I12 -> -933.39581
A14: Outright price | C14: =IFERROR(INDEX('List of customer'!P:P,MATCH($S$1,'List of customer'!$B:$B,0)),"") -> 22634
A15: Maintenance rate | C15: =IFERROR(INDEX('List of customer'!Q:Q,MATCH($S$1,'List of customer'!$B:$B,0)),"") -> 2873 | E15: Dr Bank | I15: =SUMIFS($E$39:$E$74,$B$39:$B$74,"<="&$L$1,$B$39:$B$74,">="&$L$2) -> 4893 | J15: <= Lease payment received
A16: Included for (years) | C16: =LEFT(IFERROR(INDEX('List of customer'!S:S,MATCH($S$1,'List of customer'!$B:$B,0)),""),1) -> 3 | E16: Cr Lease receivables | I16: =-SUMIFS($F$39:$F$74,$B$39:$B$74,"<="&$L$1,$B$39:$B$74,">="&$L$2) -> -1534.9963 | J16: <= Principal portion of lease payment received
A17: Net outright price for machine | C17: =C14-C15*C16 -> 14015 | E17: Cr Revenue - finance interest income | I17: =-SUMIFS($D$39:$D$74,$B$39:$B$74,"<="&$L$1,$B$39:$B$74,">="&$L$2) -> -3358.0037 | J17: <= Interest portion of lease payment received
A19: Lease payment proportion
A20: Total lease payment | C20: =C5*C8 -> 25164
A21: Total maintenance fee | C21: =C15*C16 -> 8619 | D21: <= Maintenance price is fixed across the timeline
A22: Total payable for machine | C22: =C20-C21 -> 16545
A24: Lease principal proportion
A25: Lease portion | C25: =$C$22/$C$20*$C$30 -> 9214.6787
A26: Maintenance portion | C26: =$C$21/$C$20*$C$30 -> 4800.3213
A28: Derived calculations
A29: Monthly discount rate used | C29: =IF(UPPER($C$11)="YES",RATE($C$5,-$C$8,$C$9,0,0),$C$10) -> 0.035831723
A30: Net investment in lease (PV of lease payments) | C30: =IF(UPPER($C$11)="YES",$C$9,PV($C$29,$C$5,-$C$8,0,0)) -> 14015
A31: Revenue at commencement | C31: =C30 -> 14015
A32: Cost of sales at commencement | C32: =IFERROR(INDEX('List of customer'!N:N,MATCH($S$1,'List of customer'!$B:$B,0)),"") -> 10000
A33: Selling profit at commencement | C33: =C31-C32 -> 4015
A37: Amortisation schedule
A38: Period | B38: Date | C38: Opening balance | D38: Finance income | E38: Cash received | F38: Principal reduction | G38: Closing balance
A39: 1 | B39: =$C$6 -> 45809 | C39: =C30 -> 14015 | D39: =C39*$C$29 -> 502.18159 | E39: =IF(C39<=1,0,$C$8) -> 699 | F39: =E39-D39 -> 196.81841 | G39: =C39-F39 -> 13818.182
A40: 2 | B40: =EDATE(B39,1) -> 45839 | C40: =IF(G39<=0,0,G39) -> 13818.182 | D40: =C40*$C$29 -> 495.12925 | E40: =IF(C40<=1,0,$C$8) -> 699 | F40: =E40-D40 -> 203.87075 | G40: =C40-F40 -> 13614.311
A41: 3 | B41: =EDATE(B40,1) -> 45870 | C41: =IF(G40<=0,0,G40) -> 13614.311 | D41: =C41*$C$29 -> 487.82421 | E41: =IF(C41<=1,0,$C$8) -> 699 | F41: =E41-D41 -> 211.17579 | G41: =C41-F41 -> 13403.135
A42: 4 | B42: =EDATE(B41,1) -> 45901 | C42: =IF(G41<=0,0,G41) -> 13403.135 | D42: =C42*$C$29 -> 480.25742 | E42: =IF(C42<=1,0,$C$8) -> 699 | F42: =E42-D42 -> 218.74258 | G42: =C42-F42 -> 13184.392
A43: 5 | B43: =EDATE(B42,1) -> 45931 | C43: =IF(G42<=0,0,G42) -> 13184.392 | D43: =C43*$C$29 -> 472.41949 | E43: =IF(C43<=1,0,$C$8) -> 699 | F43: =E43-D43 -> 226.58051 | G43: =C43-F43 -> 12957.812
A44: 6 | B44: =EDATE(B43,1) -> 45962 | C44: =IF(G43<=0,0,G43) -> 12957.812 | D44: =C44*$C$29 -> 464.30072 | E44: =IF(C44<=1,0,$C$8) -> 699 | F44: =E44-D44 -> 234.69928 | G44: =C44-F44 -> 12723.113
A45: 7 | B45: =EDATE(B44,1) -> 45992 | C45: =IF(G44<=0,0,G44) -> 12723.113 | D45: =C45*$C$29 -> 455.89104 | E45: =IF(C45<=1,0,$C$8) -> 699 | F45: =E45-D45 -> 243.10896 | G45: =C45-F45 -> 12480.004
A46: 8 | B46: =EDATE(B45,1) -> 46023 | C46: =IF(G45<=0,0,G45) -> 12480.004 | D46: =C46*$C$29 -> 447.18003 | E46: =IF(C46<=1,0,$C$8) -> 699 | F46: =E46-D46 -> 251.81997 | G46: =C46-F46 -> 12228.184
A47: 9 | B47: =EDATE(B46,1) -> 46054 | C47: =IF(G46<=0,0,G46) -> 12228.184 | D47: =C47*$C$29 -> 438.15689 | E47: =IF(C47<=1,0,$C$8) -> 699 | F47: =E47-D47 -> 260.84311 | G47: =C47-F47 -> 11967.341
...

Sheet SO25-0135
A1: =IFERROR(INDEX('List of customer'!D:D,MATCH($S$1,'List of customer'!$B:$B,0)),"") -> Craven F&B | K1: Year end | L1: 46022 | S1: {=MID(CELL("filename",A1),FIND("]",CELL("filename",A1))+1,255)} -> SO25-0135 | Z1: SO25-0135
E2: Account double entry | I2: =SUM(I3:I18) -> 0 | K2: Year beginning | L2: 45658
A3: INPUTS | C3: =IFERROR(INDEX('List of customer'!C:C,MATCH($S$1,'List of customer'!$B:$B,0)),"") -> Rent-to-own ice machine | E3: Initial recognition
A4: Machine cost (inventory) | C4: =IFERROR(INDEX('List of customer'!N:N,MATCH($S$1,'List of customer'!$B:$B,0)),"") -> 13451.699 | E4: Dr Lease receivables | I4: =$C$39 -> 13279.235 | J4: <= Total principal
A5: Lease term (months) | C5: =LEFT(IFERROR(INDEX('List of customer'!G:G,MATCH($S$1,'List of customer'!$B:$B,0)),""),2) -> 24 | E5: Cr Revenue - finance lease selling price | I5: =-C25 -> -10300.52 | J5: <= Machine proportion of principal
A6: Contract start | C6: =IFERROR(INDEX('List of customer'!E:E,MATCH($S$1,'List of customer'!$B:$B,0)),"") -> 45962 | E6: Cr Deferred revenue - maintenance | I6: =-C26 -> -2978.7146 | J6: <= Maintenance proportion of principal
A7: Contract end | C7: =IFERROR(INDEX('List of customer'!F:F,MATCH($S$1,'List of customer'!$B:$B,0)),"") -> 46691
A8: Monthly lease payment | C8: =IFERROR(INDEX('List of customer'!J:J,MATCH($S$1,'List of customer'!$B:$B,0)),"") -> 850 | E8: Dr Cost of Sales | I8: =C32 -> 13451.699
A9: Option 1: Cash selling price | C9: =C17 -> 13279.235 | E9: Cr Inventory | I9: =-I8 -> -13451.699 | J9: <= Inventory cost of machine
A11: Use selling price? Enter "Yes" or "No" | C11: =IF(C9=0,"No","Yes") -> Yes | E11: Recognition of maintenance
E12: Dr Deferred revenue - maintenance | I12: =-I6/$C$5*COUNTIFS($B$39:$B$74,"<="&$L$1,$E$39:$E$74,">"&0,$B$39:$B$74,">="&$L$2) -> 248.22622 | J12: <= Maintenance charged on straight-line basis
A13: Cash selling price | E13: Cr Revenue - maintenance | I13: =-I12 -> -248.22622
A14: Outright price | C14: =IFERROR(INDEX('List of customer'!P:P,MATCH($S$1,'List of customer'!$B:$B,0)),"") -> 17855.235
A15: Maintenance rate | C15: =IFERROR(INDEX('List of customer'!Q:Q,MATCH($S$1,'List of customer'!$B:$B,0)),"") -> 2288 | E15: Dr Bank | I15: =SUMIFS($E$39:$E$74,$B$39:$B$74,"<="&$L$1,$B$39:$B$74,">="&$L$2) -> 1700 | J15: <= Lease payment received
A16: Included for (years) | C16: =LEFT(IFERROR(INDEX('List of customer'!S:S,MATCH($S$1,'List of customer'!$B:$B,0)),""),1) -> 2 | E16: Cr Lease receivables | I16: =-SUMIFS($F$39:$F$74,$B$39:$B$74,"<="&$L$1,$B$39:$B$74,">="&$L$2) -> -713.60093 | J16: <= Principal portion of lease payment received
A17: Net outright price for machine | C17: =C14-C15*C16 -> 13279.235 | E17: Cr Revenue - finance interest income | I17: =-SUMIFS($D$39:$D$74,$B$39:$B$74,"<="&$L$1,$B$39:$B$74,">="&$L$2) -> -986.39907 | J17: <= Interest portion of lease payment received
A19: Lease payment proportion
A20: Total lease payment | C20: =C5*C8 -> 20400
A21: Total maintenance fee | C21: =C15*C16 -> 4576 | D21: <= Maintenance price is fixed across the timeline
A22: Total payable for machine | C22: =C20-C21 -> 15824
A24: Lease principal proportion
A25: Lease portion | C25: =$C$22/$C$20*$C$30 -> 10300.52
A26: Maintenance portion | C26: =$C$21/$C$20*$C$30 -> 2978.7146
A28: Derived calculations
A29: Monthly discount rate used | C29: =IF(UPPER($C$11)="YES",RATE($C$5,-$C$8,$C$9,0,0),$C$10) -> 0.037636955
A30: Net investment in lease (PV of lease payments) | C30: =IF(UPPER($C$11)="YES",$C$9,PV($C$29,$C$5,-$C$8,0,0)) -> 13279.235
A31: Revenue at commencement | C31: =C30 -> 13279.235
A32: Cost of sales at commencement | C32: =IFERROR(INDEX('List of customer'!N:N,MATCH($S$1,'List of customer'!$B:$B,0)),"") -> 13451.699
A33: Selling profit at commencement | C33: =C31-C32 -> -172.464
A37: Amortisation schedule
A38: Period | B38: Date | C38: Opening balance | D38: Finance income | E38: Cash received | F38: Principal reduction | G38: Closing balance
A39: 1 | B39: =$C$6 -> 45962 | C39: =C30 -> 13279.235 | D39: =C39*$C$29 -> 499.78996 | E39: =IF(C39<=1,0,$C$8) -> 850 | F39: =E39-D39 -> 350.21004 | G39: =C39-F39 -> 12929.025
A40: 2 | B40: =EDATE(B39,1) -> 45992 | C40: =IF(G39<=0,0,G39) -> 12929.025 | D40: =C40*$C$29 -> 486.60912 | E40: =IF(C40<=1,0,$C$8) -> 850 | F40: =E40-D40 -> 363.39088 | G40: =C40-F40 -> 12565.634
A41: 3 | B41: =EDATE(B40,1) -> 46023 | C41: =IF(G40<=0,0,G40) -> 12565.634 | D41: =C41*$C$29 -> 472.93219 | E41: =IF(C41<=1,0,$C$8) -> 850 | F41: =E41-D41 -> 377.06781 | G41: =C41-F41 -> 12188.566
A42: 4 | B42: =EDATE(B41,1) -> 46054 | C42: =IF(G41<=0,0,G41) -> 12188.566 | D42: =C42*$C$29 -> 458.74051 | E42: =IF(C42<=1,0,$C$8) -> 850 | F42: =E42-D42 -> 391.25949 | G42: =C42-F42 -> 11797.307
A43: 5 | B43: =EDATE(B42,1) -> 46082 | C43: =IF(G42<=0,0,G42) -> 11797.307 | D43: =C43*$C$29 -> 444.01469 | E43: =IF(C43<=1,0,$C$8) -> 850 | F43: =E43-D43 -> 405.98531 | G43: =C43-F43 -> 11391.321
A44: 6 | B44: =EDATE(B43,1) -> 46113 | C44: =IF(G43<=0,0,G43) -> 11391.321 | D44: =C44*$C$29 -> 428.73464 | E44: =IF(C44<=1,0,$C$8) -> 850 | F44: =E44-D44 -> 421.26536 | G44: =C44-F44 -> 10970.056
A45: 7 | B45: =EDATE(B44,1) -> 46143 | C45: =IF(G44<=0,0,G44) -> 10970.056 | D45: =C45*$C$29 -> 412.8795 | E45: =IF(C45<=1,0,$C$8) -> 850 | F45: =E45-D45 -> 437.1205 | G45: =C45-F45 -> 10532.935
A46: 8 | B46: =EDATE(B45,1) -> 46174 | C46: =IF(G45<=0,0,G45) -> 10532.935 | D46: =C46*$C$29 -> 396.42761 | E46: =IF(C46<=1,0,$C$8) -> 850 | F46: =E46-D46 -> 453.57239 | G46: =C46-F46 -> 10079.363
A47: 9 | B47: =EDATE(B46,1) -> 46204 | C47: =IF(G46<=0,0,G46) -> 10079.363 | D47: =C47*$C$29 -> 379.35653 | E47: =IF(C47<=1,0,$C$8) -> 850 | F47: =E47-D47 -> 470.64347 | G47: =C47-F47 -> 9608.7195
...

Sheet SO25-0138
A1: =IFERROR(INDEX('List of customer'!D:D,MATCH($S$1,'List of customer'!$B:$B,0)),"") -> Nyonya Recipe | K1: Year end | L1: 46022 | S1: {=MID(CELL("filename",A1),FIND("]",CELL("filename",A1))+1,255)} -> SO25-0138 | Z1: SO25-0138
E2: Account double entry | I2: =SUM(I3:I18) -> 0 | K2: Year beginning | L2: 45658
A3: INPUTS | C3: =IFERROR(INDEX('List of customer'!C:C,MATCH($S$1,'List of customer'!$B:$B,0)),"") -> Rent-to-own ice machine | E3: Initial recognition
A4: Machine cost (inventory) | C4: =IFERROR(INDEX('List of customer'!N:N,MATCH($S$1,'List of customer'!$B:$B,0)),"") -> 5517.6629 | E4: Dr Lease receivables | I4: =$C$39 -> 10711 | J4: <= Total principal
A5: Lease term (months) | C5: =LEFT(IFERROR(INDEX('List of customer'!G:G,MATCH($S$1,'List of customer'!$B:$B,0)),""),2) -> 24 | E5: Cr Revenue - finance lease selling price | I5: =-C25 -> -7515.0209 | J5: <= Machine proportion of principal
A6: Contract start | C6: =IFERROR(INDEX('List of customer'!E:E,MATCH($S$1,'List of customer'!$B:$B,0)),"") -> 45946 | E6: Cr Deferred revenue - maintenance | I6: =-C26 -> -3195.9791 | J6: <= Maintenance proportion of principal
A7: Contract end | C7: =IFERROR(INDEX('List of customer'!F:F,MATCH($S$1,'List of customer'!$B:$B,0)),"") -> 46675
A8: Monthly lease payment | C8: =IFERROR(INDEX('List of customer'!J:J,MATCH($S$1,'List of customer'!$B:$B,0)),"") -> 639 | E8: Dr Cost of Sales | I8: =C32 -> 5517.6629
A9: Option 1: Cash selling price | C9: =C17 -> 10711 | E9: Cr Inventory | I9: =-I8 -> -5517.6629 | J9: <= Inventory cost of machine
A11: Use selling price? Enter "Yes" or "No" | C11: =IF(C9=0,"No","Yes") -> Yes | E11: Recognition of maintenance
E12: Dr Deferred revenue - maintenance | I12: =-I6/$C$5*COUNTIFS($B$39:$B$74,"<="&$L$1,$E$39:$E$74,">"&0,$B$39:$B$74,">="&$L$2) -> 399.49739 | J12: <= Maintenance charged on straight-line basis
A13: Cash selling price | E13: Cr Revenue - maintenance | I13: =-I12 -> -399.49739
A14: Outright price | C14: =IFERROR(INDEX('List of customer'!P:P,MATCH($S$1,'List of customer'!$B:$B,0)),"") -> 15287
A15: Maintenance rate | C15: =IFERROR(INDEX('List of customer'!Q:Q,MATCH($S$1,'List of customer'!$B:$B,0)),"") -> 2288 | E15: Dr Bank | I15: =SUMIFS($E$39:$E$74,$B$39:$B$74,"<="&$L$1,$B$39:$B$74,">="&$L$2) -> 1917 | J15: <= Lease payment received
A16: Included for (years) | C16: =LEFT(IFERROR(INDEX('List of customer'!S:S,MATCH($S$1,'List of customer'!$B:$B,0)),""),1) -> 2 | E16: Cr Lease receivables | I16: =-SUMIFS($F$39:$F$74,$B$39:$B$74,"<="&$L$1,$B$39:$B$74,">="&$L$2) -> -951.0787 | J16: <= Principal portion of lease payment received
A17: Net outright price for machine | C17: =C14-C15*C16 -> 10711 | E17: Cr Revenue - finance interest income | I17: =-SUMIFS($D$39:$D$74,$B$39:$B$74,"<="&$L$1,$B$39:$B$74,">="&$L$2) -> -965.9213 | J17: <= Interest portion of lease payment received
A19: Lease payment proportion
A20: Total lease payment | C20: =C5*C8 -> 15336
A21: Total maintenance fee | C21: =C15*C16 -> 4576 | D21: <= Maintenance price is fixed across the timeline
A22: Total payable for machine | C22: =C20-C21 -> 10760
A24: Lease principal proportion
A25: Lease portion | C25: =$C$22/$C$20*$C$30 -> 7515.0209
A26: Maintenance portion | C26: =$C$21/$C$20*$C$30 -> 3195.9791
A28: Derived calculations
A29: Monthly discount rate used | C29: =IF(UPPER($C$11)="YES",RATE($C$5,-$C$8,$C$9,0,0),$C$10) -> 0.030957776
A30: Net investment in lease (PV of lease payments) | C30: =IF(UPPER($C$11)="YES",$C$9,PV($C$29,$C$5,-$C$8,0,0)) -> 10711
A31: Revenue at commencement | C31: =C30 -> 10711
A32: Cost of sales at commencement | C32: =IFERROR(INDEX('List of customer'!N:N,MATCH($S$1,'List of customer'!$B:$B,0)),"") -> 5517.6629
A33: Selling profit at commencement | C33: =C31-C32 -> 5193.3371
A37: Amortisation schedule
A38: Period | B38: Date | C38: Opening balance | D38: Finance income | E38: Cash received | F38: Principal reduction | G38: Closing balance
A39: 1 | B39: =$C$6 -> 45946 | C39: =C30 -> 10711 | D39: =C39*$C$29 -> 331.58874 | E39: =IF(C39<=1,0,$C$8) -> 639 | F39: =E39-D39 -> 307.41126 | G39: =C39-F39 -> 10403.589
A40: 2 | B40: =EDATE(B39,1) -> 45977 | C40: =IF(G39<=0,0,G39) -> 10403.589 | D40: =C40*$C$29 -> 322.07197 | E40: =IF(C40<=1,0,$C$8) -> 639 | F40: =E40-D40 -> 316.92803 | G40: =C40-F40 -> 10086.661
A41: 3 | B41: =EDATE(B40,1) -> 46007 | C41: =IF(G40<=0,0,G40) -> 10086.661 | D41: =C41*$C$29 -> 312.26059 | E41: =IF(C41<=1,0,$C$8) -> 639 | F41: =E41-D41 -> 326.73941 | G41: =C41-F41 -> 9759.9213
A42: 4 | B42: =EDATE(B41,1) -> 46038 | C42: =IF(G41<=0,0,G41) -> 9759.9213 | D42: =C42*$C$29 -> 302.14546 | E42: =IF(C42<=1,0,$C$8) -> 639 | F42: =E42-D42 -> 336.85454 | G42: =C42-F42 -> 9423.0668
A43: 5 | B43: =EDATE(B42,1) -> 46069 | C43: =IF(G42<=0,0,G42) -> 9423.0668 | D43: =C43*$C$29 -> 291.71719 | E43: =IF(C43<=1,0,$C$8) -> 639 | F43: =E43-D43 -> 347.28281 | G43: =C43-F43 -> 9075.784
A44: 6 | B44: =EDATE(B43,1) -> 46097 | C44: =IF(G43<=0,0,G43) -> 9075.784 | D44: =C44*$C$29 -> 280.96609 | E44: =IF(C44<=1,0,$C$8) -> 639 | F44: =E44-D44 -> 358.03391 | G44: =C44-F44 -> 8717.7501
A45: 7 | B45: =EDATE(B44,1) -> 46128 | C45: =IF(G44<=0,0,G44) -> 8717.7501 | D45: =C45*$C$29 -> 269.88216 | E45: =IF(C45<=1,0,$C$8) -> 639 | F45: =E45-D45 -> 369.11784 | G45: =C45-F45 -> 8348.6322
A46: 8 | B46: =EDATE(B45,1) -> 46158 | C46: =IF(G45<=0,0,G45) -> 8348.6322 | D46: =C46*$C$29 -> 258.45509 | E46: =IF(C46<=1,0,$C$8) -> 639 | F46: =E46-D46 -> 380.54491 | G46: =C46-F46 -> 7968.0873
A47: 9 | B47: =EDATE(B46,1) -> 46189 | C47: =IF(G46<=0,0,G46) -> 7968.0873 | D47: =C47*$C$29 -> 246.67426 | E47: =IF(C47<=1,0,$C$8) -> 639 | F47: =E47-D47 -> 392.32574 | G47: =C47-F47 -> 7575.7616
...

Sheet SO25-0172
A1: =IFERROR(INDEX('List of customer'!D:D,MATCH($S$1,'List of customer'!$B:$B,0)),"") -> Goldhill Reserve Sdn Bhd | K1: Year end | L1: 46022 | S1: {=MID(CELL("filename",A1),FIND("]",CELL("filename",A1))+1,255)} -> SO25-0172 | Z1: SO25-0176
E2: Account double entry | I2: =SUM(I3:I18) -> 0 | K2: Year beginning | L2: 45658
A3: INPUTS | C3: =IFERROR(INDEX('List of customer'!C:C,MATCH($S$1,'List of customer'!$B:$B,0)),"") -> Rent-to-own Dishwasher | E3: Initial recognition
A4: Machine cost (inventory) | C4: =IFERROR(INDEX('List of customer'!N:N,MATCH($S$1,'List of customer'!$B:$B,0)),"") -> 10000 | E4: Dr Lease receivables | I4: =$C$39 -> 14015 | J4: <= Total principal
A5: Lease term (months) | C5: =LEFT(IFERROR(INDEX('List of customer'!G:G,MATCH($S$1,'List of customer'!$B:$B,0)),""),2) -> 36 | E5: Cr Revenue - finance lease selling price | I5: =-C25 -> -9214.6787 | J5: <= Machine proportion of principal
A6: Contract start | C6: =IFERROR(INDEX('List of customer'!E:E,MATCH($S$1,'List of customer'!$B:$B,0)),"") -> 46023 | E6: Cr Deferred revenue - maintenance | I6: =-C26 -> -4800.3213 | J6: <= Maintenance proportion of principal
A7: Contract end | C7: =IFERROR(INDEX('List of customer'!F:F,MATCH($S$1,'List of customer'!$B:$B,0)),"") -> 47118
A8: Monthly lease payment | C8: =IFERROR(INDEX('List of customer'!J:J,MATCH($S$1,'List of customer'!$B:$B,0)),"") -> 699 | E8: Dr Cost of Sales | I8: =C32 -> 10000
A9: Option 1: Cash selling price | C9: =C17 -> 14015 | E9: Cr Inventory | I9: =-I8 -> -10000 | J9: <= Inventory cost of machine
A11: Use selling price? Enter "Yes" or "No" | C11: =IF(C9=0,"No","Yes") -> Yes | E11: Recognition of maintenance
E12: Dr Deferred revenue - maintenance | I12: =-I6/$C$5*COUNTIFS($B$39:$B$74,"<="&$L$1,$E$39:$E$74,">"&0,$B$39:$B$74,">="&$L$2) -> 0 | J12: <= Maintenance charged on straight-line basis
A13: Cash selling price | E13: Cr Revenue - maintenance | I13: =-I12 -> 0
A14: Outright price | C14: =IFERROR(INDEX('List of customer'!P:P,MATCH($S$1,'List of customer'!$B:$B,0)),"") -> 22634
A15: Maintenance rate | C15: =IFERROR(INDEX('List of customer'!Q:Q,MATCH($S$1,'List of customer'!$B:$B,0)),"") -> 2873 | E15: Dr Bank | I15: =SUMIFS($E$39:$E$74,$B$39:$B$74,"<="&$L$1,$B$39:$B$74,">="&$L$2) -> 0 | J15: <= Lease payment received
A16: Included for (years) | C16: =LEFT(IFERROR(INDEX('List of customer'!S:S,MATCH($S$1,'List of customer'!$B:$B,0)),""),1) -> 3 | E16: Cr Lease receivables | I16: =-SUMIFS($F$39:$F$74,$B$39:$B$74,"<="&$L$1,$B$39:$B$74,">="&$L$2) -> 0 | J16: <= Principal portion of lease payment received
A17: Net outright price for machine | C17: =C14-C15*C16 -> 14015 | E17: Cr Revenue - finance interest income | I17: =-SUMIFS($D$39:$D$74,$B$39:$B$74,"<="&$L$1,$B$39:$B$74,">="&$L$2) -> 0 | J17: <= Interest portion of lease payment received
A19: Lease payment proportion
A20: Total lease payment | C20: =C5*C8 -> 25164
A21: Total maintenance fee | C21: =C15*C16 -> 8619 | D21: <= Maintenance price is fixed across the timeline
A22: Total payable for machine | C22: =C20-C21 -> 16545
A24: Lease principal proportion
A25: Lease portion | C25: =$C$22/$C$20*$C$30 -> 9214.6787
A26: Maintenance portion | C26: =$C$21/$C$20*$C$30 -> 4800.3213
A28: Derived calculations
A29: Monthly discount rate used | C29: =IF(UPPER($C$11)="YES",RATE($C$5,-$C$8,$C$9,0,0),$C$10) -> 0.035831723
A30: Net investment in lease (PV of lease payments) | C30: =IF(UPPER($C$11)="YES",$C$9,PV($C$29,$C$5,-$C$8,0,0)) -> 14015
A31: Revenue at commencement | C31: =C30 -> 14015
A32: Cost of sales at commencement | C32: =IFERROR(INDEX('List of customer'!N:N,MATCH($S$1,'List of customer'!$B:$B,0)),"") -> 10000
A33: Selling profit at commencement | C33: =C31-C32 -> 4015
A37: Amortisation schedule
A38: Period | B38: Date | C38: Opening balance | D38: Finance income | E38: Cash received | F38: Principal reduction | G38: Closing balance
A39: 1 | B39: =$C$6 -> 46023 | C39: =C30 -> 14015 | D39: =C39*$C$29 -> 502.18159 | E39: =IF(C39<=1,0,$C$8) -> 699 | F39: =E39-D39 -> 196.81841 | G39: =C39-F39 -> 13818.182
A40: 2 | B40: =EDATE(B39,1) -> 46054 | C40: =IF(G39<=0,0,G39) -> 13818.182 | D40: =C40*$C$29 -> 495.12925 | E40: =IF(C40<=1,0,$C$8) -> 699 | F40: =E40-D40 -> 203.87075 | G40: =C40-F40 -> 13614.311
A41: 3 | B41: =EDATE(B40,1) -> 46082 | C41: =IF(G40<=0,0,G40) -> 13614.311 | D41: =C41*$C$29 -> 487.82421 | E41: =IF(C41<=1,0,$C$8) -> 699 | F41: =E41-D41 -> 211.17579 | G41: =C41-F41 -> 13403.135
A42: 4 | B42: =EDATE(B41,1) -> 46113 | C42: =IF(G41<=0,0,G41) -> 13403.135 | D42: =C42*$C$29 -> 480.25742 | E42: =IF(C42<=1,0,$C$8) -> 699 | F42: =E42-D42 -> 218.74258 | G42: =C42-F42 -> 13184.392
A43: 5 | B43: =EDATE(B42,1) -> 46143 | C43: =IF(G42<=0,0,G42) -> 13184.392 | D43: =C43*$C$29 -> 472.41949 | E43: =IF(C43<=1,0,$C$8) -> 699 | F43: =E43-D43 -> 226.58051 | G43: =C43-F43 -> 12957.812
A44: 6 | B44: =EDATE(B43,1) -> 46174 | C44: =IF(G43<=0,0,G43) -> 12957.812 | D44: =C44*$C$29 -> 464.30072 | E44: =IF(C44<=1,0,$C$8) -> 699 | F44: =E44-D44 -> 234.69928 | G44: =C44-F44 -> 12723.113
A45: 7 | B45: =EDATE(B44,1) -> 46204 | C45: =IF(G44<=0,0,G44) -> 12723.113 | D45: =C45*$C$29 -> 455.89104 | E45: =IF(C45<=1,0,$C$8) -> 699 | F45: =E45-D45 -> 243.10896 | G45: =C45-F45 -> 12480.004
A46: 8 | B46: =EDATE(B45,1) -> 46235 | C46: =IF(G45<=0,0,G45) -> 12480.004 | D46: =C46*$C$29 -> 447.18003 | E46: =IF(C46<=1,0,$C$8) -> 699 | F46: =E46-D46 -> 251.81997 | G46: =C46-F46 -> 12228.184
A47: 9 | B47: =EDATE(B46,1) -> 46266 | C47: =IF(G46<=0,0,G46) -> 12228.184 | D47: =C47*$C$29 -> 438.15689 | E47: =IF(C47<=1,0,$C$8) -> 699 | F47: =E47-D47 -> 260.84311 | G47: =C47-F47 -> 11967.341
...
